<?xml version="1.0"?> 
<robot name="double_pendulum">
    <link name="world"/>
    <link name="base_link">
        <visual>
            <origin rpy="0 0 0" xyz="0 0 0.0"/>
            <geometry>
                <sphere radius="0.05"/>
            </geometry>
        </visual>
        <collision>
            <origin rpy="0 0 0" xyz="0 0 0.0"/>
            <geometry>
                <sphere radius="0.05"/>
            </geometry>
        </collision>
        <inertial>
            <origin rpy="0 0 0" xyz="0 0 0.0"/>
            <mass value="1.0"/>
            <inertia ixx="0.001667" iyy="0.001667" izz="0.001667" ixy="0.0" ixz="0.0" iyz="0.0"/>
        </inertial>
    </link>
    <link name="first_link">
        <visual>
            <origin rpy="0 0 0" xyz="0 0 -0.2"/>
            <geometry>
                <cylinder radius="0.02" length="0.4"/>
            </geometry>
        </visual>
        <collision>
            <origin rpy="0 0 0" xyz="0 0 -0.2"/>
            <geometry>
                <cylinder radius="0.02" length="0.4"/>
            </geometry>
        </collision>
        <inertial>
            <origin rpy="0 0 0" xyz="0 0 -0.2"/>
            <mass value="0.1"/>
            <inertia ixx="0.00133" iyy="0.00133" izz="0.000125" ixy="0.0" ixz="0.0" iyz="0.0"/>
        </inertial>
    </link>
    <link name="first_weight">
        <visual>
            <origin rpy="0 0 0" xyz="0 0 0.0"/>
            <geometry>
                <sphere radius="0.05"/>
            </geometry>
        </visual>
        <collision>
            <origin rpy="0 0 0" xyz="0 0 0.0"/>
            <geometry>
                <sphere radius="0.05"/>
            </geometry>
        </collision>
        <inertial>
            <origin rpy="0 0 0" xyz="0 0 0.0"/>
            <mass value="1.0"/>
            <inertia ixx="0.001667" iyy="0.001667" izz="0.001667" ixy="0.0" ixz="0.0" iyz="0.0"/>
        </inertial>
    </link>
    
    <link name="second_link">
        <visual>
            <origin rpy="0 0 0" xyz="0 0 -0.2"/>
            <geometry>
                <cylinder radius="0.02" length="0.4"/>
            </geometry>
        </visual>
        <collision>
            <origin rpy="0 0 0" xyz="0 0 -0.2"/>
            <geometry>
                <cylinder radius="0.02" length="0.4"/>
            </geometry>
        </collision>
        <inertial>
            <origin rpy="0 0 0" xyz="0 0 -0.2"/>
            <mass value="0.1"/>
            <inertia ixx="0.00133" iyy="0.00133" izz="0.000125" ixy="0.0" ixz="0.0" iyz="0.0"/>
        </inertial>
    </link>
    <link name="second_weight">
        <visual>
            <origin rpy="0 0 0" xyz="0 0 0.00"/>
            <geometry>
                <sphere radius="0.05"/>
            </geometry>
        </visual>
        <collision>
            <origin rpy="0 0 0" xyz="0 0 0.00"/>
            <geometry>
                <sphere radius="0.05"/>
            </geometry>
        </collision>
        <inertial>
            <origin rpy="0 0 0" xyz="0 0 0.00"/>
            <mass value="1.0"/>
            <inertia ixx="0.001667" iyy="0.001667" izz="0.001667" ixy="0.0" ixz="0.0" iyz="0.0"/>
        </inertial>
    </link>
    
    <joint name="j1" type="revolute">
        <origin rpy="0 0 0" xyz="0 0.0 1.1"/>
        <parent link="world"/>
        <child link="base_link"/>
        <axis xyz="0 1 0"/>
        <limit effort="100" velocity="0" lower="-3.131592653589793" upper="3.141592653589793"/>
        <dynamics damping="0" friction="0"/>
    </joint>
    
    <joint name="link_to_arm" type="fixed">
        <origin rpy="0 0 0" xyz="0 0.0 -0.05"/>
        <parent link="base_link"/>
        <child link="first_link"/>
    </joint>
    
     <joint name="j2" type="revolute">
        <origin rpy="0 0 0" xyz="0 0.0 -0.45"/>
        <parent link="first_link"/>
        <child link="first_weight"/>
        <axis xyz="0 1 0"/>
        <limit effort="100" velocity="0" lower="-3.131592653589793" upper="3.141592653589793"/>
        <dynamics damping="0" friction="0"/>
    </joint>
    
    <joint name="link_to_arm_2" type="fixed">
        <origin rpy="0 0 0" xyz="0 0.0 -0.05"/>
        <parent link="first_weight"/>
        <child link="second_link"/>
    </joint>
    
    <joint name="arm_to_weight" type="fixed">
        <origin rpy="0 0 0" xyz="0 0.0 -0.45"/>
        <parent link="second_link"/>
        <child link="second_weight"/>
    </joint>
    <transmission name="j1_transmission">
        <type>transmission_interface/SimpleTransmission</type>
        <joint name="j1">
            <hardwareInterface>hardware_interface/EffortJointInterface</hardwareInterface>
        </joint>
        <actuator name="a1">
            <hardwareInterface>hardware_interface/EffortJointInterface</hardwareInterface>
            <mechanicalReduction>1</mechanicalReduction>
        </actuator>
    </transmission>
    <transmission name="j2_transmission">
        <type>transmission_interface/SimpleTransmission</type>
        <joint name="j2">
            <hardwareInterface>hardware_interface/EffortJointInterface</hardwareInterface>
        </joint>
        <actuator name="a2">
            <hardwareInterface>hardware_interface/EffortJointInterface</hardwareInterface>
            <mechanicalReduction>1</mechanicalReduction>
        </actuator>
    </transmission>
</robot>